<?xml version="1.0" ?>
<!-- =================================================================================== -->
<!-- |    This document was autogenerated by xacro from rv7fl.urdf.xacro               | -->
<!-- |    EDITING THIS FILE BY HAND IS NOT RECOMMENDED                                 | -->
<!-- =================================================================================== -->
<!-- Copyright (C) 2018, Tokyo Opensource Robotics Kyokai Association -->
<robot name="rv7fl" xmlns:xacro="http://www.ros.org/wiki/xacro">
  <material name="white">
    <color rgba="1.0 1.0 1.0 1.0"/>
  </material>
  <link name="base_link"/>
  <joint name="rv7fl_mounting_joint" type="fixed">
    <origin rpy="0 0 0" xyz="0 0 0"/>
    <parent link="base_link"/>
    <child link="link0"/>
  </joint>
  <link name="link0">
    <visual>
      <origin rpy="0 0 0" xyz="0 0 0"/>
      <geometry>
        <mesh filename="package://melfa_description/mesh/rv7fl/L0.stl" scale="1.4 1.4 1.1"/>
      </geometry>
      <material name="white"/>
    </visual>
    <collision>
      <origin rpy="0 0 0" xyz="0 0 0"/>
      <geometry>
        <mesh filename="package://melfa_description/mesh/rv7fl/L0.stl" scale="1.4 1.4 1.1"/>
      </geometry>
    </collision>
  </link>
  <joint name="joint1" type="revolute">
    <parent link="link0"/>
    <child link="link1"/>
    <origin rpy="0 0 0" xyz="0 0 0.4"/>
    <axis xyz="0 0 1"/>
    <dynamics damping="0.7"/>
    <limit effort="10" lower="-4.18879020479" upper="4.18879020479" velocity="5.02654824574"/>
  </joint>
  <link name="link1">
    <visual>
      <origin rpy="0 0 0" xyz="0 0 0"/>
      <geometry>
        <mesh filename="package://melfa_description/mesh/rv7fl/L1.stl" scale="1.3 1.3 1.3"/>
      </geometry>
      <material name="white"/>
    </visual>
    <collision>
      <origin rpy="0 0 0" xyz="0 0 0"/>
      <geometry>
        <mesh filename="package://melfa_description/mesh/rv7fl/L1.stl" scale="1.3 1.3 1.3"/>
      </geometry>
    </collision>
  </link>
  <joint name="joint2" type="revolute">
    <parent link="link1"/>
    <child link="link2"/>
    <origin rpy="0 0 0" xyz="0 0 0"/>
    <axis xyz="0 1 0"/>
    <dynamics damping="0.7"/>
    <limit effort="10" lower="-1.91986217719" upper="2.26892802759" velocity="5.6025068989"/>
  </joint>
  <link name="link2">
    <visual>
      <origin rpy="0 0 0" xyz="0 0 0"/>
      <geometry>
        <mesh filename="package://melfa_description/mesh/rv7fl/L2.stl" scale="1.45 1.45 1.45"/>
      </geometry>
      <material name="white"/>
    </visual>
    <collision>
      <origin rpy="0 0 0" xyz="0 0 0"/>
      <geometry>
        <mesh filename="package://melfa_description/mesh/rv7fl/L2.stl" scale="1.45 1.45 1.45"/>
      </geometry>
    </collision>
  </link>
  <joint name="joint3" type="revolute">
    <parent link="link2"/>
    <child link="link3"/>
    <origin rpy="0 0 0" xyz="0 0 0.435"/>
    <axis xyz="0 1 0"/>
    <dynamics damping="0.7"/>
    <limit effort="10" lower="0.00" upper="2.82743338823" velocity="6.28318530718"/>
  </joint>
  <link name="link3">
    <visual>
      <origin rpy="0 0 0" xyz="0 0 0"/>
      <geometry>
        <mesh filename="package://melfa_description/mesh/rv7fl/L3.stl" scale="1.3 1.3 1.3"/>
      </geometry>
      <material name="white"/>
    </visual>
    <collision>
      <origin rpy="0 0 0" xyz="0 0 0"/>
      <geometry>
        <mesh filename="package://melfa_description/mesh/rv7fl/L3.stl" scale="1.3 1.3 1.3"/>
      </geometry>
    </collision>
  </link>
  <joint name="joint4" type="revolute">
    <parent link="link3"/>
    <child link="link4"/>
    <origin rpy="0 0 0" xyz="-0.05 0 0.47"/>
    <axis xyz="0 0 1"/>
    <dynamics damping="0.7"/>
    <limit effort="10" lower="-3.49065850399" upper="3.49065850399" velocity="5.88175957922"/>
  </joint>
  <link name="link4">
    <visual>
      <origin rpy="0 0 0" xyz="0 0 0"/>
      <geometry>
        <mesh filename="package://melfa_description/mesh/rv7fl/L4.stl" scale="1.4 1.4 1.4"/>
      </geometry>
      <material name="white"/>
    </visual>
    <collision>
      <origin rpy="0 0 0" xyz="0 0 0"/>
      <geometry>
        <mesh filename="package://melfa_description/mesh/rv7fl/L4.stl" scale="1.4 1.4 1.4"/>
      </geometry>
    </collision>
  </link>
  <joint name="joint5" type="revolute">
    <parent link="link4"/>
    <child link="link5"/>
    <origin rpy="0 0 0" xyz="0 0 0"/>
    <axis xyz="0 1 0"/>
    <dynamics damping="0.7"/>
    <limit effort="10" lower="-2.09439510239" upper="2.09439510239" velocity="7.85398163397"/>
  </joint>
  <link name="link5">
    <visual>
      <origin rpy="0 0 0" xyz="0 0 0"/>
      <geometry>
        <mesh filename="package://melfa_description/mesh/rv7fl/L5.stl" scale="1.4 1.4 1.4"/>
      </geometry>
      <material name="white"/>
    </visual>
    <collision>
      <origin rpy="0 0 0" xyz="0 0 0"/>
      <geometry>
        <mesh filename="package://melfa_description/mesh/rv7fl/L5.stl" scale="1.4 1.4 1.4"/>
      </geometry>
    </collision>
  </link>
  <joint name="joint6" type="revolute">
    <parent link="link5"/>
    <child link="link6"/>
    <origin rpy="0 0 0" xyz="0 0 0.085"/>
    <axis xyz="0 0 1"/>
    <dynamics damping="0.7"/>
    <limit effort="10" lower="-6.28318530718" upper="6.28318530718" velocity="12.5663706144"/>
  </joint>
  <link name="link6">
    <visual>
      <origin rpy="0 0 0" xyz="0 0 0"/>
      <geometry>
        <mesh filename="package://melfa_description/mesh/rv7fl/L6.stl"/>
      </geometry>
      <material name="white"/>
    </visual>
    <collision>
      <origin rpy="0 0 0" xyz="0 0 0"/>
      <geometry>
        <mesh filename="package://melfa_description/mesh/rv7fl/L6.stl"/>
      </geometry>
    </collision>
  </link>
</robot>

