<?xml version="1.0" encoding="utf-8"?>
<!-- =================================================================================== -->
<!-- |    This document was autogenerated by xacro from rv7fr-dh-floor.urdf.xacro      | -->
<!-- |    EDITING THIS FILE BY HAND IS NOT RECOMMENDED                                 | -->
<!-- =================================================================================== -->
<!--[ ] Add Gazebo plugin for ros control-->
<!--[ ] Add sensor model plugin -->
<!--[ ] Check the correct limits efforts
     [119.36611817, 107.16168698,  50.92959239,  17.00171377, 12.7323981 ,   3.97887346] -->
<!--[DONE] Check if the transmission matched the joint number -->
<robot name="rv7fr">
  <material name="white">
    <color rgba="1.0 0.980392156863 0.898039215686 1."/>
  </material>
  <material name="silver">
    <color rgba="0.61568627451 0.839215686275 0.941176470588 1."/>
  </material>
  <link name="world"/>
  <link name="floor">
    <visual>
      <geometry>
        <mesh filename="package://melfa_description/mesh/rv7fr/floor.stl" scale="0.001 0.001 0.001"/>
      </geometry>
      <origin rpy="0 0 0" xyz="0 0 0"/>
      <material name="white"/>
    </visual>
    <collision>
      <origin rpy="0 0 0" xyz="0 0 0"/>
      <geometry>
        <mesh filename="package://melfa_description/mesh/rv7fr/floor.stl" scale="0.001 0.001 0.001"/>
      </geometry>
    </collision>
    <inertial>
      <!--origin
        xyz="-0.11257 -4.1589E-05 0.057533"
        rpy="0 0 0" /-->
      <!-- I am using the density of Alumide (1.36g/cm^3) for this -->
      <!-- The volume of the mesh is 13038.131 cm^3 -->
      <mass value="17.73185816"/>
      <inertia ixx="103.908878848" ixy="6.363055616" ixz="-6.148561408" iyy="139.111661568" iyz="2.115191296" izz="132.604526592"/>
    </inertial>
    <!--inertial-->
  </link>
  <joint name="flooring" type="fixed">
    <parent link="world"/>
    <child link="floor"/>
  </joint>
  <link name="base">
    <visual>
      <geometry>
        <mesh filename="package://melfa_description/mesh/rv7fr/dh_base.stl" scale="0.001 0.001 0.001"/>
      </geometry>
      <origin rpy="0 0 0" xyz="0 0 0"/>
      <material name="white"/>
    </visual>
    <collision>
      <origin rpy="0 0 0" xyz="0 0 0"/>
      <geometry>
        <mesh filename="package://melfa_description/mesh/rv7fr/dh_base.stl" scale="0.001 0.001 0.001"/>
      </geometry>
    </collision>
    <inertial>
      <!--origin
        xyz="-0.11257 -4.1589E-05 0.057533"
        rpy="0 0 0" /-->
      <!-- I am using the density of Alumide (1.36g/cm^3) for this -->
      <!-- The volume of the mesh is 13038.131 cm^3 -->
      <mass value="17.73185816"/>
      <inertia ixx="103.908878848" ixy="6.363055616" ixz="-6.148561408" iyy="139.111661568" iyz="2.115191296" izz="132.604526592"/>
    </inertial>
    <!--inertial-->
  </link>
  <!--Fixed joint-->
  <joint name="joint_w" type="fixed">
    <parent link="floor"/>
    <child link="base"/>
    <origin rpy="0 0 0" xyz="0 0 0.01"/>
  </joint>
  <link name="link1">
    <visual>
      <origin rpy="0 0 0" xyz="0 0 0"/>
      <geometry>
        <mesh filename="package://melfa_description/mesh/rv7fr/dh_link1.stl" scale="0.001 0.001 0.001"/>
      </geometry>
      <material name="white"/>
    </visual>
    <inertial>
      <!--origin
        xyz="-0.11257 -4.1589E-05 0.057533"
        rpy="0 0 0" /-->
      <!-- I am using the density of Alumide (1.36g/cm^3) for this -->
      <!-- The volume of the mesh is 6013.742500000 cm^3 -->
      <mass value="8.1786898"/>
      <inertia ixx="90.376159232" ixy="0.016287799" ixz="-1.10389888" iyy="52.040425472" iyz="0.255685056" izz="66.680070144"/>
    </inertial>
    <!--inertial-->
    <collision>
      <origin rpy="0 0 0" xyz="0 0 0"/>
      <geometry>
        <mesh filename="package://melfa_description/mesh/rv7fr/dh_link1.stl" scale="0.001 0.001 0.001"/>
      </geometry>
    </collision>
  </link>
  <joint name="joint1" type="revolute">
    <parent link="base"/>
    <child link="link1"/>
    <origin rpy="0.0 0.0 0.0" xyz="0 0 0.225"/>
    <axis xyz="0 0 1"/>
    <!--Effort in this context is in N.m (revolute joint)-->
    <limit effort="119.36611817" lower="-4.18879020533" upper="4.18879020533" velocity="6.283185308"/>
    <dynamics damping="0" friction="0"/>
  </joint>
  <transmission name="trans1">
    <type>transmission_interface/SimpleTransmission</type>
    <joint name="joint1">
      <hardwareInterface>PositionJointInterface</hardwareInterface>
    </joint>
    <actuator name="motor1">
      <hardwareInterface>PositionJointInterface</hardwareInterface>
      <mechanicalReduction>1</mechanicalReduction>
    </actuator>
  </transmission>
  <link name="link2">
    <visual>
      <origin rpy="0 0 0" xyz="0 0 0"/>
      <geometry>
        <mesh filename="package://melfa_description/mesh/rv7fr/dh_link2.stl" scale="0.001 0.001 0.001"/>
      </geometry>
      <material name="white"/>
    </visual>
    <inertial>
      <!--origin
        xyz="-0.11257 -4.1589E-05 0.057533"
        rpy="0 0 0" /-->
      <!-- I am using the density of Alumide (1.36g/cm^3) for this -->
      <!-- The volume of the mesh is 9326.481 cm^3 -->
      <mass value="12.68401416"/>
      <inertia ixx="51.839111168" ixy="3.830765824" ixz="-1.103037056" iyy="192.674725888" iyz="0.112871744" izz="176.385097728"/>
    </inertial>
    <!--inertial-->
    <collision>
      <origin rpy="0 0 0" xyz="0 0 0"/>
      <geometry>
        <mesh filename="package://melfa_description/mesh/rv7fr/dh_link2.stl" scale="0.001 0.001 0.001"/>
      </geometry>
    </collision>
  </link>
  <joint name="joint2" type="revolute">
    <parent link="link1"/>
    <child link="link2"/>
    <origin rpy="-1.570796327 0.0 0.0" xyz="0. 0. 0.175"/>
    <axis xyz="0 0 1"/>
    <!--Effort in this context is in N.m (revolute joint)-->
    <limit effort="107.16168698" lower="-3.43829862688" upper="0.610865238278" velocity="6.99877030141"/>
    <dynamics damping="0" friction="0"/>
  </joint>
  <transmission name="trans2">
    <type>transmission_interface/SimpleTransmission</type>
    <joint name="joint2">
      <hardwareInterface>PositionJointInterface</hardwareInterface>
    </joint>
    <actuator name="motor2">
      <hardwareInterface>PositionJointInterface</hardwareInterface>
      <mechanicalReduction>1</mechanicalReduction>
    </actuator>
  </transmission>
  <link name="link3">
    <visual>
      <origin rpy="0 0 0" xyz="0 0 0"/>
      <geometry>
        <mesh filename="package://melfa_description/mesh/rv7fr/dh_link3.stl" scale="0.001 0.001 0.001"/>
      </geometry>
      <material name="white"/>
    </visual>
    <inertial>
      <!--origin
        xyz="-0.11257 -4.1589E-05 0.057533"
        rpy="0 0 0" /-->
      <!-- I am using the density of Alumide (1.36g/cm^3) for this -->
      <!-- The volume of the mesh is 3836.328250000 cm^3 -->
      <mass value="5.21740642"/>
      <inertia ixx="15.117059072" ixy="-1.406446848" ixz="-0.060891936" iyy="13.858434048" iyz="-0.067995424" izz="17.11241216"/>
    </inertial>
    <!--inertial-->
    <collision>
      <origin rpy="0 0 0" xyz="0 0 0"/>
      <geometry>
        <mesh filename="package://melfa_description/mesh/rv7fr/dh_link3.stl" scale="0.001 0.001 0.001"/>
      </geometry>
    </collision>
  </link>
  <joint name="joint3" type="revolute">
    <parent link="link2"/>
    <child link="link3"/>
    <origin rpy="0 0 0" xyz="0.34 0 0"/>
    <axis xyz="0 0 1"/>
    <!--Effort in this context is in N.m (revolute joint)-->
    <limit effort="50.92959239" lower="-1.570796327" upper="1.15191730647" velocity="7.853981635"/>
    <dynamics damping="0" friction="0"/>
  </joint>
  <transmission name="trans3">
    <type>transmission_interface/SimpleTransmission</type>
    <joint name="joint3">
      <hardwareInterface>PositionJointInterface</hardwareInterface>
    </joint>
    <actuator name="motor3">
      <hardwareInterface>PositionJointInterface</hardwareInterface>
      <mechanicalReduction>1</mechanicalReduction>
    </actuator>
  </transmission>
  <link name="link4">
    <visual>
      <origin rpy="0 0 0" xyz="0 0 0.095"/>
      <geometry>
        <mesh filename="package://melfa_description/mesh/rv7fr/dh_link4.stl" scale="0.001 0.001 0.001"/>
      </geometry>
      <material name="white"/>
    </visual>
    <inertial>
      <!--origin
        xyz="-0.11257 -4.1589E-05 0.057533"
        rpy="0 0 0" /-->
      <!-- I am using the density of Alumide (1.36g/cm^3) for this -->
      <!-- The volume of the mesh is 2815.481250000  cm^3 -->
      <mass value="3.8290545"/>
      <inertia ixx="20.911454208" ixy="0.000388218125" ixz="-0.136878256" iyy="19.643154432" iyz="0.053645312" izz="5.443939328"/>
    </inertial>
    <!--inertial-->
    <collision>
      <origin rpy="0 0 0" xyz="0 0 0.095"/>
      <geometry>
        <mesh filename="package://melfa_description/mesh/rv7fr/dh_link4.stl" scale="0.001 0.001 0.001"/>
      </geometry>
    </collision>
  </link>
  <joint name="joint4" type="revolute">
    <parent link="link3"/>
    <child link="link4"/>
    <origin rpy="-1.570796327 0 0" xyz="0.05 0 0"/>
    <axis xyz="0 0 1"/>
    <!--Effort in this context is in N.m (revolute joint)-->
    <limit effort="16.2" lower="-3.49065850444" upper="3.49065850444" velocity="5.88175957999"/>
    <dynamics damping="0" friction="0"/>
  </joint>
  <transmission name="trans4">
    <type>transmission_interface/SimpleTransmission</type>
    <joint name="joint4">
      <hardwareInterface>PositionJointInterface</hardwareInterface>
    </joint>
    <actuator name="motor4">
      <hardwareInterface>PositionJointInterface</hardwareInterface>
      <mechanicalReduction>1</mechanicalReduction>
    </actuator>
  </transmission>
  <link name="link5">
    <visual>
      <origin rpy="0 0 0" xyz="0 0 0"/>
      <geometry>
        <mesh filename="package://melfa_description/mesh/rv7fr/dh_link5.stl" scale="0.001 0.001 0.001"/>
      </geometry>
      <material name="white"/>
    </visual>
    <inertial>
      <!--origin
        xyz="-0.11257 -4.1589E-05 0.057533"
        rpy="0 0 0" /-->
      <!-- I am using the density of Alumide (1.36g/cm^3) for this -->
      <!-- The volume of the mesh is 586.139875000 cm^3 -->
      <mass value="0.79715023"/>
      <inertia ixx="0.809056896" ixy="-0.015322087" ixz="-0.0005321248125" iyy="0.50428528" iyz="-0.000197501046875" izz="0.90484512"/>
    </inertial>
    <!--inertial-->
    <collision>
      <origin rpy="0 0 0" xyz="0 0 0"/>
      <geometry>
        <mesh filename="package://melfa_description/mesh/rv7fr/dh_link5.stl" scale="0.001 0.001 0.001"/>
      </geometry>
    </collision>
  </link>
  <joint name="joint5" type="revolute">
    <parent link="link4"/>
    <child link="link5"/>
    <origin rpy="1.570796327 0 0" xyz="0 0 0.3695"/>
    <axis xyz="0 0 1"/>
    <!--Effort in this context is in N.m (revolute joint)-->
    <limit effort="16.2" lower="-2.09439510267" upper="2.09439510267" velocity="7.853981635"/>
    <dynamics damping="0" friction="0"/>
  </joint>
  <transmission name="trans5">
    <type>transmission_interface/SimpleTransmission</type>
    <joint name="joint5">
      <hardwareInterface>PositionJointInterface</hardwareInterface>
    </joint>
    <actuator name="motor5">
      <hardwareInterface>PositionJointInterface</hardwareInterface>
      <mechanicalReduction>1</mechanicalReduction>
    </actuator>
  </transmission>
  <link name="link6">
    <visual>
      <origin rpy="0 0 0" xyz="0 0 0.085"/>
      <geometry>
        <mesh filename="package://melfa_description/mesh/rv7fr/dh_link6.stl" scale="0.001 0.001 0.001"/>
      </geometry>
      <material name="white"/>
    </visual>
    <inertial>
      <!--origin
        xyz="-0.11257 -4.1589E-05 0.057533"
        rpy="0 0 0" /-->
      <!-- I am using the density of Alumide (1.36g/cm^3) for this -->
      <!-- The volume of the mesh is  18.648947266 cm^3 -->
      <mass value="0.0253625682818"/>
      <inertia ixx="0.002339714" ixy="2.550886e-09" ixz="1.4813418945e-05" iyy="0.00230009425" iyz="6.07867e-09" izz="0.00342455025"/>
    </inertial>
    <!--inertial-->
    <collision>
      <origin rpy="0 0 0" xyz="0 0 0.085"/>
      <geometry>
        <mesh filename="package://melfa_description/mesh/rv7fr/dh_link6.stl" scale="0.001 0.001 0.001"/>
      </geometry>
    </collision>
  </link>
  <joint name="joint6" type="revolute">
    <parent link="link5"/>
    <child link="link6"/>
    <origin rpy="-1.570796327 0 0" xyz="0 0 0"/>
    <axis xyz="0 0 1"/>
    <!--Effort in this context is in N.m (revolute joint)-->
    <limit effort="6.86" lower="-6.283185308" upper="6.283185308" velocity="12.566370616"/>
    <dynamics damping="0" friction="0"/>
  </joint>
  <transmission name="trans6">
    <type>transmission_interface/SimpleTransmission</type>
    <joint name="joint6">
      <hardwareInterface>PositionJointInterface</hardwareInterface>
    </joint>
    <actuator name="motor6">
      <hardwareInterface>PositionJointInterface</hardwareInterface>
      <mechanicalReduction>1</mechanicalReduction>
    </actuator>
  </transmission>
  <!-- Dummy/Buffer joint for inverse kinematics -->
  <link name="link_effector"/>
  <joint name="joint_effector" type="fixed">
    <parent link="link6"/>
    <child link="link_effector"/>
    <origin rpy="0 0 0" xyz="0 0 0.085"/>
    <axis xyz="0 0 0"/>
  </joint>
</robot>
